Workbook

Sheet Sheet1
A1: Brand Partner Order Projections
A3: Item Total by Month
A4: JUVIA'S PLACE (52853)
A5: Report Generated: 1/28/2026 8:15:30 PM
A7: General Information | M7: 2026 P01 | N7: 2026 P02 | O7: 2026 P03 | P7: 2026 P04 | Q7: 2026 P05 | R7: 2026 P06 | S7: 2026 P07 | T7: 2026 P08 | U7: 2026 P09 | V7: 2026 P10 | W7: 2026 P11 | X7: 2026 P12
A8: UPC# | B8: ULTA Item# | C8: ULTA Item Description | E8: Brand Partner SKU# | F8: Department | G8: Brand # | H8: Retail Item Rank | I8: Feature Code | J8: Season Code | K8: Purchase Cost (Average) | L8: Retail Price (Current) | M8: February | N8: March | O8: April | P8: May | Q8: June | R8: July | S8: August | T8: September | U8: October | V8: November | W8: December | X8: January | AJ8: Current | AK8: Past | AL8: Delta
A9: Overall Result | M9: 178126 | N9: 214138 | O9: 237182 | P9: 205374 | Q9: 215320 | R9: 269098 | S9: 221360 | T9: 231522 | U9: 317806 | V9: 367876 | W9: 249064 | X9: 357776 | AA9: 13 | AB9: =AA9+1 -> 14 | AC9: =AB9+1 -> 15 | AD9: =AC9+1 -> 16 | AE9: =AD9+1 -> 17 | AF9: =AE9+1 -> 18 | AG9: =AF9+1 -> 19 | AH9: =AG9+1 -> 20
A10: 869001000347 | B10: 2536080 | C10: THE SAHARAN BLUSH PALETTE | E10: 1000361 | F10: 021 | G10: 3453 - JUVIA'S PLACE | I10: X | J10: BASC | K10: 9 | L10: 18 | M10: 0 | N10: 0 | O10: 0 | P10: 0 | Q10: 0 | R10: 0 | S10: 0 | T10: 0 | U10: 0 | V10: 0 | W10: 0 | X10: 0 | Z10: =VLOOKUP(E10,Sheet2!$A$1:$A$39,1,0) -> #N/A | AA10: =VLOOKUP($E10,[1]Sheet1!$E$10:$X$629,AA$9,0) -> 0 | AB10: =VLOOKUP($E10,[1]Sheet1!$E$10:$X$629,AB$9,0) -> 0 | AC10: =VLOOKUP($E10,[1]Sheet1!$E$10:$X$629,AC$9,0) -> 0 | AD10: =VLOOKUP($E10,[1]Sheet1!$E$10:$X$629,AD$9,0) -> 0 | AE10: =VLOOKUP($E10,[1]Sheet1!$E$10:$X$629,AE$9,0) -> 0 | AF10: =VLOOKUP($E10,[1]Sheet1!$E$10:$X$629,AF$9,0) -> 0 | AG10: =VLOOKUP($E10,[1]Sheet1!$E$10:$X$629,AG$9,0) -> 0 | AH10: =VLOOKUP($E10,[1]Sheet1!$E$10:$X$629,AH$9,0) -> 0 | AJ10: =SUM(M10:T10) -> 0 | AK10: =SUM(AA10:AH10) -> 0 | AL10: =IFERROR(AJ10-AK10,0) -> 0
A11: 869001000248 | B11: 2536081 | C11: THE MASQUERADE MINI EYESHADOW PALETTE | E11: 1000091 | F11: 021 | G11: 3453 - JUVIA'S PLACE | H11: C | I11: DI | J11: BASC | K11: 12.5 | L11: 2.5 | M11: 0 | N11: 0 | O11: 0 | P11: 0 | Q11: 0 | R11: 0 | S11: 0 | T11: 0 | U11: 0 | V11: 0 | W11: 0 | X11: 0 | Z11: =VLOOKUP(E11,Sheet2!$A$1:$A$39,1,0) -> #N/A | AA11: =VLOOKUP($E11,[1]Sheet1!$E$10:$X$629,AA$9,0) -> 0 | AB11: =VLOOKUP($E11,[1]Sheet1!$E$10:$X$629,AB$9,0) -> 0 | AC11: =VLOOKUP($E11,[1]Sheet1!$E$10:$X$629,AC$9,0) -> 0 | AD11: =VLOOKUP($E11,[1]Sheet1!$E$10:$X$629,AD$9,0) -> 0 | AE11: =VLOOKUP($E11,[1]Sheet1!$E$10:$X$629,AE$9,0) -> 0 | AF11: =VLOOKUP($E11,[1]Sheet1!$E$10:$X$629,AF$9,0) -> 0 | AG11: =VLOOKUP($E11,[1]Sheet1!$E$10:$X$629,AG$9,0) -> 0 | AH11: =VLOOKUP($E11,[1]Sheet1!$E$10:$X$629,AH$9,0) -> 0 | AJ11: =SUM(M11:T11) -> 0 | AK11: =SUM(AA11:AH11) -> 0 | AL11: =IFERROR(AJ11-AK11,0) -> 0
A12: 869001000316 | B12: 2536082 | C12: THE ZULU EYESHADOW PALETTE 1.14OZ | E12: 1000369 | F12: 021 | G12: 3453 - JUVIA'S PLACE | H12: E | I12: A | J12: BASC | K12: 12.5 | L12: 25 | M12: 720 | N12: 1008 | O12: 1152 | P12: 936 | Q12: 720 | R12: 792 | S12: 720 | T12: 1008 | U12: 1224 | V12: 1944 | W12: 648 | X12: 1872 | Z12: =VLOOKUP(E12,Sheet2!$A$1:$A$39,1,0) -> #N/A | AA12: =VLOOKUP($E12,[1]Sheet1!$E$10:$X$629,AA$9,0) -> 720 | AB12: =VLOOKUP($E12,[1]Sheet1!$E$10:$X$629,AB$9,0) -> 792 | AC12: =VLOOKUP($E12,[1]Sheet1!$E$10:$X$629,AC$9,0) -> 1008 | AD12: =VLOOKUP($E12,[1]Sheet1!$E$10:$X$629,AD$9,0) -> 720 | AE12: =VLOOKUP($E12,[1]Sheet1!$E$10:$X$629,AE$9,0) -> 576 | AF12: =VLOOKUP($E12,[1]Sheet1!$E$10:$X$629,AF$9,0) -> 648 | AG12: =VLOOKUP($E12,[1]Sheet1!$E$10:$X$629,AG$9,0) -> 648 | AH12: =VLOOKUP($E12,[1]Sheet1!$E$10:$X$629,AH$9,0) -> 216 | AJ12: =SUM(M12:T12) -> 7056 | AK12: =SUM(AA12:AH12) -> 5328 | AL12: =IFERROR(AJ12-AK12,0) -> 1728
A13: 869001000231 | B13: 2536083 | C13: THE SAHARAN EYESHADOW PALETTE SAHARAN | E13: 1000359 | F13: 021 | G13: 3453 - JUVIA'S PLACE | H13: F | I13: A | J13: BASC | K13: 12.5 | L13: 25 | M13: 288 | N13: 480 | O13: 480 | P13: 384 | Q13: 288 | R13: 384 | S13: 384 | T13: 384 | U13: 480 | V13: 1344 | W13: 672 | X13: 1056 | Z13: =VLOOKUP(E13,Sheet2!$A$1:$A$39,1,0) -> #N/A | AA13: =VLOOKUP($E13,[1]Sheet1!$E$10:$X$629,AA$9,0) -> 384 | AB13: =VLOOKUP($E13,[1]Sheet1!$E$10:$X$629,AB$9,0) -> 192 | AC13: =VLOOKUP($E13,[1]Sheet1!$E$10:$X$629,AC$9,0) -> 576 | AD13: =VLOOKUP($E13,[1]Sheet1!$E$10:$X$629,AD$9,0) -> 288 | AE13: =VLOOKUP($E13,[1]Sheet1!$E$10:$X$629,AE$9,0) -> 288 | AF13: =VLOOKUP($E13,[1]Sheet1!$E$10:$X$629,AF$9,0) -> 480 | AG13: =VLOOKUP($E13,[1]Sheet1!$E$10:$X$629,AG$9,0) -> 192 | AH13: =VLOOKUP($E13,[1]Sheet1!$E$10:$X$629,AH$9,0) -> 192 | AJ13: =SUM(M13:T13) -> 3072 | AK13: =SUM(AA13:AH13) -> 2592 | AL13: =IFERROR(AJ13-AK13,0) -> 480
A14: 857494007271 | B14: 2536084 | C14: THE MAGIC MINI EYESHADOW PALETTE | E14: 4007271 | F14: 021 | G14: 3453 - JUVIA'S PLACE | I14: X | J14: BASC | K14: 12.5 | L14: 12.49 | M14: 0 | N14: 0 | O14: 0 | P14: 0 | Q14: 0 | R14: 0 | S14: 0 | T14: 0 | U14: 0 | V14: 0 | W14: 0 | X14: 0 | Z14: =VLOOKUP(E14,Sheet2!$A$1:$A$39,1,0) -> #N/A | AA14: =VLOOKUP($E14,[1]Sheet1!$E$10:$X$629,AA$9,0) -> 0 | AB14: =VLOOKUP($E14,[1]Sheet1!$E$10:$X$629,AB$9,0) -> 0 | AC14: =VLOOKUP($E14,[1]Sheet1!$E$10:$X$629,AC$9,0) -> 0 | AD14: =VLOOKUP($E14,[1]Sheet1!$E$10:$X$629,AD$9,0) -> 0 | AE14: =VLOOKUP($E14,[1]Sheet1!$E$10:$X$629,AE$9,0) -> 0 | AF14: =VLOOKUP($E14,[1]Sheet1!$E$10:$X$629,AF$9,0) -> 0 | AG14: =VLOOKUP($E14,[1]Sheet1!$E$10:$X$629,AG$9,0) -> 0 | AH14: =VLOOKUP($E14,[1]Sheet1!$E$10:$X$629,AH$9,0) -> 0 | AJ14: =SUM(M14:T14) -> 0 | AK14: =SUM(AA14:AH14) -> 0 | AL14: =IFERROR(AJ14-AK14,0) -> 0
A15: 869001000279 | B15: 2536085 | C15: THE SAHARAN BLUSH PALETTE | E15: 1000360 | F15: 021 | G15: 3453 - JUVIA'S PLACE | I15: DI | J15: BASC | K15: 9 | L15: 18 | M15: 0 | N15: 0 | O15: 0 | P15: 0 | Q15: 0 | R15: 0 | S15: 0 | T15: 0 | U15: 0 | V15: 0 | W15: 0 | X15: 0 | Z15: =VLOOKUP(E15,Sheet2!$A$1:$A$39,1,0) -> #N/A | AA15: =VLOOKUP($E15,[1]Sheet1!$E$10:$X$629,AA$9,0) -> 0 | AB15: =VLOOKUP($E15,[1]Sheet1!$E$10:$X$629,AB$9,0) -> 0 | AC15: =VLOOKUP($E15,[1]Sheet1!$E$10:$X$629,AC$9,0) -> 0 | AD15: =VLOOKUP($E15,[1]Sheet1!$E$10:$X$629,AD$9,0) -> 0 | AE15: =VLOOKUP($E15,[1]Sheet1!$E$10:$X$629,AE$9,0) -> 0 | AF15: =VLOOKUP($E15,[1]Sheet1!$E$10:$X$629,AF$9,0) -> 0 | AG15: =VLOOKUP($E15,[1]Sheet1!$E$10:$X$629,AG$9,0) -> 0 | AH15: =VLOOKUP($E15,[1]Sheet1!$E$10:$X$629,AH$9,0) -> 0 | AJ15: =SUM(M15:T15) -> 0 | AK15: =SUM(AA15:AH15) -> 0 | AL15: =IFERROR(AJ15-AK15,0) -> 0
A16: 857494007097 | B16: 2536086 | C16: THE EYESHADOW PALETTE | E16: 1000338 | F16: 021 | G16: 3453 - JUVIA'S PLACE | I16: X | J16: BASC | K16: 10 | L16: 20 | M16: 0 | N16: 0 | O16: 0 | P16: 0 | Q16: 0 | R16: 0 | S16: 0 | T16: 0 | U16: 0 | V16: 0 | W16: 0 | X16: 0 | Z16: =VLOOKUP(E16,Sheet2!$A$1:$A$39,1,0) -> #N/A | AA16: =VLOOKUP($E16,[1]Sheet1!$E$10:$X$629,AA$9,0) -> 0 | AB16: =VLOOKUP($E16,[1]Sheet1!$E$10:$X$629,AB$9,0) -> 0 | AC16: =VLOOKUP($E16,[1]Sheet1!$E$10:$X$629,AC$9,0) -> 0 | AD16: =VLOOKUP($E16,[1]Sheet1!$E$10:$X$629,AD$9,0) -> 0 | AE16: =VLOOKUP($E16,[1]Sheet1!$E$10:$X$629,AE$9,0) -> 0 | AF16: =VLOOKUP($E16,[1]Sheet1!$E$10:$X$629,AF$9,0) -> 0 | AG16: =VLOOKUP($E16,[1]Sheet1!$E$10:$X$629,AG$9,0) -> 0 | AH16: =VLOOKUP($E16,[1]Sheet1!$E$10:$X$629,AH$9,0) -> 0 | AJ16: =SUM(M16:T16) -> 0 | AK16: =SUM(AA16:AH16) -> 0 | AL16: =IFERROR(AJ16-AK16,0) -> 0
A17: 857494007288 | B17: 2536087 | C17: THE WARRIOR EYESHADOW PALETTE WARRIOR | E17: 1000367 | F17: 021 | G17: 3453 - JUVIA'S PLACE | H17: E | I17: A | J17: BASC | K17: 12.5 | L17: 25 | M17: 936 | N17: 1296 | O17: 1152 | P17: 1080 | Q17: 1152 | R17: 1368 | S17: 1368 | T17: 1296 | U17: 2376 | V17: 2448 | W17: 792 | X17: 2520 | Z17: =VLOOKUP(E17,Sheet2!$A$1:$A$39,1,0) -> #N/A | AA17: =VLOOKUP($E17,[1]Sheet1!$E$10:$X$629,AA$9,0) -> 1296 | AB17: =VLOOKUP($E17,[1]Sheet1!$E$10:$X$629,AB$9,0) -> 1584 | AC17: =VLOOKUP($E17,[1]Sheet1!$E$10:$X$629,AC$9,0) -> 1800 | AD17: =VLOOKUP($E17,[1]Sheet1!$E$10:$X$629,AD$9,0) -> 1584 | AE17: =VLOOKUP($E17,[1]Sheet1!$E$10:$X$629,AE$9,0) -> 1368 | AF17: =VLOOKUP($E17,[1]Sheet1!$E$10:$X$629,AF$9,0) -> 1872 | AG17: =VLOOKUP($E17,[1]Sheet1!$E$10:$X$629,AG$9,0) -> 1872 | AH17: =VLOOKUP($E17,[1]Sheet1!$E$10:$X$629,AH$9,0) -> 720 | AJ17: =SUM(M17:T17) -> 9648 | AK17: =SUM(AA17:AH17) -> 12096 | AL17: =IFERROR(AJ17-AK17,0) -> -2448
A18: 857494007295 | B18: 2536088 | C18: THE WARRIOR EYESHADOW PALETTE WARRIOR II | E18: 1000368 | F18: 021 | G18: 3453 - JUVIA'S PLACE | H18: E | I18: A | J18: BASC | K18: 12.5 | L18: 25 | M18: 720 | N18: 1008 | O18: 936 | P18: 936 | Q18: 936 | R18: 1152 | S18: 936 | T18: 1080 | U18: 1368 | V18: 2160 | W18: 720 | X18: 2016 | Z18: =VLOOKUP(E18,Sheet2!$A$1:$A$39,1,0) -> #N/A | AA18: =VLOOKUP($E18,[1]Sheet1!$E$10:$X$629,AA$9,0) -> 936 | AB18: =VLOOKUP($E18,[1]Sheet1!$E$10:$X$629,AB$9,0) -> 1008 | AC18: =VLOOKUP($E18,[1]Sheet1!$E$10:$X$629,AC$9,0) -> 1152 | AD18: =VLOOKUP($E18,[1]Sheet1!$E$10:$X$629,AD$9,0) -> 864 | AE18: =VLOOKUP($E18,[1]Sheet1!$E$10:$X$629,AE$9,0) -> 936 | AF18: =VLOOKUP($E18,[1]Sheet1!$E$10:$X$629,AF$9,0) -> 1224 | AG18: =VLOOKUP($E18,[1]Sheet1!$E$10:$X$629,AG$9,0) -> 1080 | AH18: =VLOOKUP($E18,[1]Sheet1!$E$10:$X$629,AH$9,0) -> 504 | AJ18: =SUM(M18:T18) -> 7704 | AK18: =SUM(AA18:AH18) -> 7704 | AL18: =IFERROR(AJ18-AK18,0) -> 0
A19: 857494007523 | B19: 2536090 | C19: AFRIQUE EYESHADOW PALETTE | E19: 1000085 | F19: 021 | G19: 3453 - JUVIA'S PLACE | I19: X | J19: BASC | K19: 10 | L19: 20 | M19: 0 | N19: 0 | O19: 0 | P19: 0 | Q19: 0 | R19: 0 | S19: 0 | T19: 0 | U19: 0 | V19: 0 | W19: 0 | X19: 0 | Z19: =VLOOKUP(E19,Sheet2!$A$1:$A$39,1,0) -> #N/A | AA19: =VLOOKUP($E19,[1]Sheet1!$E$10:$X$629,AA$9,0) -> 0 | AB19: =VLOOKUP($E19,[1]Sheet1!$E$10:$X$629,AB$9,0) -> 0 | AC19: =VLOOKUP($E19,[1]Sheet1!$E$10:$X$629,AC$9,0) -> 0 | AD19: =VLOOKUP($E19,[1]Sheet1!$E$10:$X$629,AD$9,0) -> 0 | AE19: =VLOOKUP($E19,[1]Sheet1!$E$10:$X$629,AE$9,0) -> 0 | AF19: =VLOOKUP($E19,[1]Sheet1!$E$10:$X$629,AF$9,0) -> 0 | AG19: =VLOOKUP($E19,[1]Sheet1!$E$10:$X$629,AG$9,0) -> 0 | AH19: =VLOOKUP($E19,[1]Sheet1!$E$10:$X$629,AH$9,0) -> 0 | AJ19: =SUM(M19:T19) -> 0 | AK19: =SUM(AA19:AH19) -> 0 | AL19: =IFERROR(AJ19-AK19,0) -> 0
A20: 857494007516 | B20: 2536093 | C20: BELLA BLUSH | E20: 1000611 | F20: 021 | G20: 3453 - JUVIA'S PLACE | I20: DI | J20: BASC | K20: 4 | L20: 8 | M20: 0 | N20: 0 | O20: 0 | P20: 0 | Q20: 0 | R20: 0 | S20: 0 | T20: 0 | U20: 0 | V20: 0 | W20: 0 | X20: 0 | Z20: =VLOOKUP(E20,Sheet2!$A$1:$A$39,1,0) -> #N/A | AA20: =VLOOKUP($E20,[1]Sheet1!$E$10:$X$629,AA$9,0) -> 0 | AB20: =VLOOKUP($E20,[1]Sheet1!$E$10:$X$629,AB$9,0) -> 0 | AC20: =VLOOKUP($E20,[1]Sheet1!$E$10:$X$629,AC$9,0) -> 0 | AD20: =VLOOKUP($E20,[1]Sheet1!$E$10:$X$629,AD$9,0) -> 0 | AE20: =VLOOKUP($E20,[1]Sheet1!$E$10:$X$629,AE$9,0) -> 0 | AF20: =VLOOKUP($E20,[1]Sheet1!$E$10:$X$629,AF$9,0) -> 0 | AG20: =VLOOKUP($E20,[1]Sheet1!$E$10:$X$629,AG$9,0) -> 0 | AH20: =VLOOKUP($E20,[1]Sheet1!$E$10:$X$629,AH$9,0) -> 0 | AJ20: =SUM(M20:T20) -> 0 | AK20: =SUM(AA20:AH20) -> 0 | AL20: =IFERROR(AJ20-AK20,0) -> 0
A21: 857494007417 | B21: 2536094 | C21: THE TRIBE HIGHLIGHTER | E21: 1000371 | F21: 021 | G21: 3453 - JUVIA'S PLACE | I21: X | J21: BASC | K21: 7.5 | L21: 15 | M21: 0 | N21: 0 | O21: 0 | P21: 0 | Q21: 0 | R21: 0 | S21: 0 | T21: 0 | U21: 0 | V21: 0 | W21: 0 | X21: 0 | Z21: =VLOOKUP(E21,Sheet2!$A$1:$A$39,1,0) -> #N/A | AA21: =VLOOKUP($E21,[1]Sheet1!$E$10:$X$629,AA$9,0) -> 0 | AB21: =VLOOKUP($E21,[1]Sheet1!$E$10:$X$629,AB$9,0) -> 0 | AC21: =VLOOKUP($E21,[1]Sheet1!$E$10:$X$629,AC$9,0) -> 0 | AD21: =VLOOKUP($E21,[1]Sheet1!$E$10:$X$629,AD$9,0) -> 0 | AE21: =VLOOKUP($E21,[1]Sheet1!$E$10:$X$629,AE$9,0) -> 0 | AF21: =VLOOKUP($E21,[1]Sheet1!$E$10:$X$629,AF$9,0) -> 0 | AG21: =VLOOKUP($E21,[1]Sheet1!$E$10:$X$629,AG$9,0) -> 0 | AH21: =VLOOKUP($E21,[1]Sheet1!$E$10:$X$629,AH$9,0) -> 0 | AJ21: =SUM(M21:T21) -> 0 | AK21: =SUM(AA21:AH21) -> 0 | AL21: =IFERROR(AJ21-AK21,0) -> 0
A22: 857494007400 | B22: 2536095 | C22: THE TRIBE HIGHLIGHTER | E22: 1000370 | F22: 021 | G22: 3453 - JUVIA'S PLACE | I22: DI | J22: BASC | K22: 7.5 | L22: 15 | M22: 0 | N22: 0 | O22: 0 | P22: 0 | Q22: 0 | R22: 0 | S22: 0 | T22: 0 | U22: 0 | V22: 0 | W22: 0 | X22: 0 | Z22: =VLOOKUP(E22,Sheet2!$A$1:$A$39,1,0) -> #N/A | AA22: =VLOOKUP($E22,[1]Sheet1!$E$10:$X$629,AA$9,0) -> 0 | AB22: =VLOOKUP($E22,[1]Sheet1!$E$10:$X$629,AB$9,0) -> 0 | AC22: =VLOOKUP($E22,[1]Sheet1!$E$10:$X$629,AC$9,0) -> 0 | AD22: =VLOOKUP($E22,[1]Sheet1!$E$10:$X$629,AD$9,0) -> 0 | AE22: =VLOOKUP($E22,[1]Sheet1!$E$10:$X$629,AE$9,0) -> 0 | AF22: =VLOOKUP($E22,[1]Sheet1!$E$10:$X$629,AF$9,0) -> 0 | AG22: =VLOOKUP($E22,[1]Sheet1!$E$10:$X$629,AG$9,0) -> 0 | AH22: =VLOOKUP($E22,[1]Sheet1!$E$10:$X$629,AH$9,0) -> 0 | AJ22: =SUM(M22:T22) -> 0 | AK22: =SUM(AA22:AH22) -> 0 | AL22: =IFERROR(AJ22-AK22,0) -> 0
A23: 857494007493 | B23: 2536096 | C23: THE HEROINE GLOW HIGHLIGHTER GLOW 2 | E23: 1000189 | F23: 021 | G23: 3453 - JUVIA'S PLACE | I23: X | J23: BASC | K23: 8.5 | L23: 17 | M23: 0 | N23: 0 | O23: 0 | P23: 0 | Q23: 0 | R23: 0 | S23: 0 | T23: 0 | U23: 0 | V23: 0 | W23: 0 | X23: 0 | Z23: =VLOOKUP(E23,Sheet2!$A$1:$A$39,1,0) -> #N/A | AA23: =VLOOKUP($E23,[1]Sheet1!$E$10:$X$629,AA$9,0) -> 0 | AB23: =VLOOKUP($E23,[1]Sheet1!$E$10:$X$629,AB$9,0) -> 0 | AC23: =VLOOKUP($E23,[1]Sheet1!$E$10:$X$629,AC$9,0) -> 0 | AD23: =VLOOKUP($E23,[1]Sheet1!$E$10:$X$629,AD$9,0) -> 0 | AE23: =VLOOKUP($E23,[1]Sheet1!$E$10:$X$629,AE$9,0) -> 0 | AF23: =VLOOKUP($E23,[1]Sheet1!$E$10:$X$629,AF$9,0) -> 0 | AG23: =VLOOKUP($E23,[1]Sheet1!$E$10:$X$629,AG$9,0) -> 0 | AH23: =VLOOKUP($E23,[1]Sheet1!$E$10:$X$629,AH$9,0) -> 0 | AJ23: =SUM(M23:T23) -> 0 | AK23: =SUM(AA23:AH23) -> 0 | AL23: =IFERROR(AJ23-AK23,0) -> 0
A24: 857494007462 | B24: 2536097 | C24: THE WARRIOR EYESHADOW PALETTE WARRIOR III | E24: 1000109 | F24: 021 | G24: 3453 - JUVIA'S PLACE | I24: X | J24: BASC | K24: 10 | L24: 6.25 | M24: 0 | N24: 0 | O24: 0 | P24: 0 | Q24: 0 | R24: 0 | S24: 0 | T24: 0 | U24: 0 | V24: 0 | W24: 0 | X24: 0 | Z24: =VLOOKUP(E24,Sheet2!$A$1:$A$39,1,0) -> #N/A | AA24: =VLOOKUP($E24,[1]Sheet1!$E$10:$X$629,AA$9,0) -> 0 | AB24: =VLOOKUP($E24,[1]Sheet1!$E$10:$X$629,AB$9,0) -> 0 | AC24: =VLOOKUP($E24,[1]Sheet1!$E$10:$X$629,AC$9,0) -> 0 | AD24: =VLOOKUP($E24,[1]Sheet1!$E$10:$X$629,AD$9,0) -> 0 | AE24: =VLOOKUP($E24,[1]Sheet1!$E$10:$X$629,AE$9,0) -> 0 | AF24: =VLOOKUP($E24,[1]Sheet1!$E$10:$X$629,AF$9,0) -> 0 | AG24: =VLOOKUP($E24,[1]Sheet1!$E$10:$X$629,AG$9,0) -> 0 | AH24: =VLOOKUP($E24,[1]Sheet1!$E$10:$X$629,AH$9,0) -> 0 | AJ24: =SUM(M24:T24) -> 0 | AK24: =SUM(AA24:AH24) -> 0 | AL24: =IFERROR(AJ24-AK24,0) -> 0
A25: 857494007486 | B25: 2536098 | C25: THE HEROINE GLOW HIGHLIGHTER GLOW 1 | E25: 1000187 | F25: 021 | G25: 3453 - JUVIA'S PLACE | I25: X | J25: BASC | K25: 8.5 | L25: 17 | M25: 0 | N25: 0 | O25: 0 | P25: 0 | Q25: 0 | R25: 0 | S25: 0 | T25: 0 | U25: 0 | V25: 0 | W25: 0 | X25: 0 | Z25: =VLOOKUP(E25,Sheet2!$A$1:$A$39,1,0) -> #N/A | AA25: =VLOOKUP($E25,[1]Sheet1!$E$10:$X$629,AA$9,0) -> 0 | AB25: =VLOOKUP($E25,[1]Sheet1!$E$10:$X$629,AB$9,0) -> 0 | AC25: =VLOOKUP($E25,[1]Sheet1!$E$10:$X$629,AC$9,0) -> 0 | AD25: =VLOOKUP($E25,[1]Sheet1!$E$10:$X$629,AD$9,0) -> 0 | AE25: =VLOOKUP($E25,[1]Sheet1!$E$10:$X$629,AE$9,0) -> 0 | AF25: =VLOOKUP($E25,[1]Sheet1!$E$10:$X$629,AF$9,0) -> 0 | AG25: =VLOOKUP($E25,[1]Sheet1!$E$10:$X$629,AG$9,0) -> 0 | AH25: =VLOOKUP($E25,[1]Sheet1!$E$10:$X$629,AH$9,0) -> 0 | AJ25: =SUM(M25:T25) -> 0 | AK25: =SUM(AA25:AH25) -> 0 | AL25: =IFERROR(AJ25-AK25,0) -> 0
A26: 857494007233 | B26: 2536100 | C26: THE ROYALTY GLOW LOOSE HIGHLIGHTER | E26: 1000810 | F26: 021 | G26: 3453 - JUVIA'S PLACE | I26: X | J26: BASC | K26: 7 | L26: 14 | M26: 0 | N26: 0 | O26: 0 | P26: 0 | Q26: 0 | R26: 0 | S26: 0 | T26: 0 | U26: 0 | V26: 0 | W26: 0 | X26: 0 | Z26: =VLOOKUP(E26,Sheet2!$A$1:$A$39,1,0) -> #N/A | AA26: =VLOOKUP($E26,[1]Sheet1!$E$10:$X$629,AA$9,0) -> 0 | AB26: =VLOOKUP($E26,[1]Sheet1!$E$10:$X$629,AB$9,0) -> 0 | AC26: =VLOOKUP($E26,[1]Sheet1!$E$10:$X$629,AC$9,0) -> 0 | AD26: =VLOOKUP($E26,[1]Sheet1!$E$10:$X$629,AD$9,0) -> 0 | AE26: =VLOOKUP($E26,[1]Sheet1!$E$10:$X$629,AE$9,0) -> 0 | AF26: =VLOOKUP($E26,[1]Sheet1!$E$10:$X$629,AF$9,0) -> 0 | AG26: =VLOOKUP($E26,[1]Sheet1!$E$10:$X$629,AG$9,0) -> 0 | AH26: =VLOOKUP($E26,[1]Sheet1!$E$10:$X$629,AH$9,0) -> 0 | AJ26: =SUM(M26:T26) -> 0 | AK26: =SUM(AA26:AH26) -> 0 | AL26: =IFERROR(AJ26-AK26,0) -> 0
A27: 857494007264 | B27: 2536101 | C27: THE SAHARAN EYESHADOW PALETTE | E27: 1000262 | F27: 021 | G27: 3453 - JUVIA'S PLACE | I27: X | J27: BASC | K27: 10 | L27: 9.99 | M27: 0 | N27: 0 | O27: 0 | P27: 0 | Q27: 0 | R27: 0 | S27: 0 | T27: 0 | U27: 0 | V27: 0 | W27: 0 | X27: 0 | Z27: =VLOOKUP(E27,Sheet2!$A$1:$A$39,1,0) -> #N/A | AA27: =VLOOKUP($E27,[1]Sheet1!$E$10:$X$629,AA$9,0) -> 0 | AB27: =VLOOKUP($E27,[1]Sheet1!$E$10:$X$629,AB$9,0) -> 0 | AC27: =VLOOKUP($E27,[1]Sheet1!$E$10:$X$629,AC$9,0) -> 0 | AD27: =VLOOKUP($E27,[1]Sheet1!$E$10:$X$629,AD$9,0) -> 0 | AE27: =VLOOKUP($E27,[1]Sheet1!$E$10:$X$629,AE$9,0) -> 0 | AF27: =VLOOKUP($E27,[1]Sheet1!$E$10:$X$629,AF$9,0) -> 0 | AG27: =VLOOKUP($E27,[1]Sheet1!$E$10:$X$629,AG$9,0) -> 0 | AH27: =VLOOKUP($E27,[1]Sheet1!$E$10:$X$629,AH$9,0) -> 0 | AJ27: =SUM(M27:T27) -> 0 | AK27: =SUM(AA27:AH27) -> 0 | AL27: =IFERROR(AJ27-AK27,0) -> 0
A28: 869001000217 | B28: 2536102 | C28: THE NUBIAN EYESHADOW PALETTE NUBIAN 2 | E28: 1000098 | F28: 021 | G28: 3453 - JUVIA'S PLACE | H28: F | I28: X | J28: BASC | K28: 10 | L28: 5 | M28: 0 | N28: 0 | O28: 0 | P28: 0 | Q28: 0 | R28: 0 | S28: 0 | T28: 0 | U28: 0 | V28: 0 | W28: 0 | X28: 0 | Z28: =VLOOKUP(E28,Sheet2!$A$1:$A$39,1,0) -> #N/A | AA28: =VLOOKUP($E28,[1]Sheet1!$E$10:$X$629,AA$9,0) -> 0 | AB28: =VLOOKUP($E28,[1]Sheet1!$E$10:$X$629,AB$9,0) -> 0 | AC28: =VLOOKUP($E28,[1]Sheet1!$E$10:$X$629,AC$9,0) -> 0 | AD28: =VLOOKUP($E28,[1]Sheet1!$E$10:$X$629,AD$9,0) -> 0 | AE28: =VLOOKUP($E28,[1]Sheet1!$E$10:$X$629,AE$9,0) -> 0 | AF28: =VLOOKUP($E28,[1]Sheet1!$E$10:$X$629,AF$9,0) -> 0 | AG28: =VLOOKUP($E28,[1]Sheet1!$E$10:$X$629,AG$9,0) -> 0 | AH28: =VLOOKUP($E28,[1]Sheet1!$E$10:$X$629,AH$9,0) -> 0 | AJ28: =SUM(M28:T28) -> 0 | AK28: =SUM(AA28:AH28) -> 0 | AL28: =IFERROR(AJ28-AK28,0) -> 0
A29: 857494007240 | B29: 2536105 | C29: THE ROYALTY GLOW LOOSE HIGHLIGHTER | E29: 1000809 | F29: 021 | G29: 3453 - JUVIA'S PLACE | I29: X | J29: BASC | K29: 7 | L29: 14 | M29: 0 | N29: 0 | O29: 0 | P29: 0 | Q29: 0 | R29: 0 | S29: 0 | T29: 0 | U29: 0 | V29: 0 | W29: 0 | X29: 0 | Z29: =VLOOKUP(E29,Sheet2!$A$1:$A$39,1,0) -> #N/A | AA29: =VLOOKUP($E29,[1]Sheet1!$E$10:$X$629,AA$9,0) -> 0 | AB29: =VLOOKUP($E29,[1]Sheet1!$E$10:$X$629,AB$9,0) -> 0 | AC29: =VLOOKUP($E29,[1]Sheet1!$E$10:$X$629,AC$9,0) -> 0 | AD29: =VLOOKUP($E29,[1]Sheet1!$E$10:$X$629,AD$9,0) -> 0 | AE29: =VLOOKUP($E29,[1]Sheet1!$E$10:$X$629,AE$9,0) -> 0 | AF29: =VLOOKUP($E29,[1]Sheet1!$E$10:$X$629,AF$9,0) -> 0 | AG29: =VLOOKUP($E29,[1]Sheet1!$E$10:$X$629,AG$9,0) -> 0 | AH29: =VLOOKUP($E29,[1]Sheet1!$E$10:$X$629,AH$9,0) -> 0 | AJ29: =SUM(M29:T29) -> 0 | AK29: =SUM(AA29:AH29) -> 0 | AL29: =IFERROR(AJ29-AK29,0) -> 0
A30: 869001000200 | B30: 2536106 | C30: THE NUBIAN EYESHADOW PALETTE NUBIAN 2 | E30: 1000097 | F30: 021 | G30: 3453 - JUVIA'S PLACE | H30: E | I30: A | J30: BASC | K30: 12.5 | L30: 25 | M30: 480 | N30: 576 | O30: 768 | P30: 480 | Q30: 480 | R30: 672 | S30: 576 | T30: 480 | U30: 1056 | V30: 1248 | W30: 576 | X30: 1152 | Z30: =VLOOKUP(E30,Sheet2!$A$1:$A$39,1,0) -> #N/A | AA30: =VLOOKUP($E30,[1]Sheet1!$E$10:$X$629,AA$9,0) -> 480 | AB30: =VLOOKUP($E30,[1]Sheet1!$E$10:$X$629,AB$9,0) -> 672 | AC30: =VLOOKUP($E30,[1]Sheet1!$E$10:$X$629,AC$9,0) -> 672 | AD30: =VLOOKUP($E30,[1]Sheet1!$E$10:$X$629,AD$9,0) -> 576 | AE30: =VLOOKUP($E30,[1]Sheet1!$E$10:$X$629,AE$9,0) -> 672 | AF30: =VLOOKUP($E30,[1]Sheet1!$E$10:$X$629,AF$9,0) -> 480 | AG30: =VLOOKUP($E30,[1]Sheet1!$E$10:$X$629,AG$9,0) -> 672 | AH30: =VLOOKUP($E30,[1]Sheet1!$E$10:$X$629,AH$9,0) -> 192 | AJ30: =SUM(M30:T30) -> 4512 | AK30: =SUM(AA30:AH30) -> 4416 | AL30: =IFERROR(AJ30-AK30,0) -> 96
A31: 857494007431 | B31: 2537042 | C31: THE NUBIAN LOOSE HIGHLIGHTER NERFERTITI | E31: 1000803 | F31: 021 | G31: 3453 - JUVIA'S PLACE | H31: E | I31: A | J31: BASC | K31: 7.5 | L31: 15 | M31: 576 | N31: 1008 | O31: 720 | P31: 720 | Q31: 576 | R31: 1008 | S31: 576 | T31: 864 | U31: 720 | V31: 1152 | W31: 1008 | X31: 720 | Z31: =VLOOKUP(E31,Sheet2!$A$1:$A$39,1,0) -> #N/A | AA31: =VLOOKUP($E31,[1]Sheet1!$E$10:$X$629,AA$9,0) -> 432 | AB31: =VLOOKUP($E31,[1]Sheet1!$E$10:$X$629,AB$9,0) -> 576 | AC31: =VLOOKUP($E31,[1]Sheet1!$E$10:$X$629,AC$9,0) -> 864 | AD31: =VLOOKUP($E31,[1]Sheet1!$E$10:$X$629,AD$9,0) -> 432 | AE31: =VLOOKUP($E31,[1]Sheet1!$E$10:$X$629,AE$9,0) -> 432 | AF31: =VLOOKUP($E31,[1]Sheet1!$E$10:$X$629,AF$9,0) -> 720 | AG31: =VLOOKUP($E31,[1]Sheet1!$E$10:$X$629,AG$9,0) -> 576 | AH31: =VLOOKUP($E31,[1]Sheet1!$E$10:$X$629,AH$9,0) -> 144 | AJ31: =SUM(M31:T31) -> 6048 | AK31: =SUM(AA31:AH31) -> 4176 | AL31: =IFERROR(AJ31-AK31,0) -> 1872
A32: 857494007424 | B32: 2537043 | C32: THE NUBIAN LOOSE HIGHLIGHTER NUBIA | E32: 1000806 | F32: 021 | G32: 3453 - JUVIA'S PLACE | I32: X | J32: BASC | K32: 7 | L32: 14 | M32: 0 | N32: 0 | O32: 0 | P32: 0 | Q32: 0 | R32: 0 | S32: 0 | T32: 0 | U32: 0 | V32: 0 | W32: 0 | X32: 0 | Z32: =VLOOKUP(E32,Sheet2!$A$1:$A$39,1,0) -> #N/A | AA32: =VLOOKUP($E32,[1]Sheet1!$E$10:$X$629,AA$9,0) -> 0 | AB32: =VLOOKUP($E32,[1]Sheet1!$E$10:$X$629,AB$9,0) -> 0 | AC32: =VLOOKUP($E32,[1]Sheet1!$E$10:$X$629,AC$9,0) -> 0 | AD32: =VLOOKUP($E32,[1]Sheet1!$E$10:$X$629,AD$9,0) -> 0 | AE32: =VLOOKUP($E32,[1]Sheet1!$E$10:$X$629,AE$9,0) -> 0 | AF32: =VLOOKUP($E32,[1]Sheet1!$E$10:$X$629,AF$9,0) -> 0 | AG32: =VLOOKUP($E32,[1]Sheet1!$E$10:$X$629,AG$9,0) -> 0 | AH32: =VLOOKUP($E32,[1]Sheet1!$E$10:$X$629,AH$9,0) -> 0 | AJ32: =SUM(M32:T32) -> 0 | AK32: =SUM(AA32:AH32) -> 0 | AL32: =IFERROR(AJ32-AK32,0) -> 0
A33: 857494007479 | B33: 2537070 | C33: THE NUBIAN EYESHADOW PALETTE NUBIAN 3 | E33: 1000351 | F33: 021 | G33: 3453 - JUVIA'S PLACE | H33: F | I33: DI | J33: BASC | K33: 10 | L33: 20 | M33: 0 | N33: 0 | O33: 0 | P33: 0 | Q33: 0 | R33: 0 | S33: 0 | T33: 0 | U33: 0 | V33: 0 | W33: 0 | X33: 0 | Z33: =VLOOKUP(E33,Sheet2!$A$1:$A$39,1,0) -> #N/A | AA33: =VLOOKUP($E33,[1]Sheet1!$E$10:$X$629,AA$9,0) -> 0 | AB33: =VLOOKUP($E33,[1]Sheet1!$E$10:$X$629,AB$9,0) -> 0 | AC33: =VLOOKUP($E33,[1]Sheet1!$E$10:$X$629,AC$9,0) -> 0 | AD33: =VLOOKUP($E33,[1]Sheet1!$E$10:$X$629,AD$9,0) -> 0 | AE33: =VLOOKUP($E33,[1]Sheet1!$E$10:$X$629,AE$9,0) -> 0 | AF33: =VLOOKUP($E33,[1]Sheet1!$E$10:$X$629,AF$9,0) -> 0 | AG33: =VLOOKUP($E33,[1]Sheet1!$E$10:$X$629,AG$9,0) -> 0 | AH33: =VLOOKUP($E33,[1]Sheet1!$E$10:$X$629,AH$9,0) -> 0 | AJ33: =SUM(M33:T33) -> 0 | AK33: =SUM(AA33:AH33) -> 0 | AL33: =IFERROR(AJ33-AK33,0) -> 0
A34: 857494007110 | B34: 2546937 | C34: THE NUBIAN LOOSE HIGHLIGHTER | E34: 1000800 | F34: 021 | G34: 3453 - JUVIA'S PLACE | H34: C | I34: X | J34: BASC | K34: 7 | L34: 14 | M34: 0 | N34: 0 | O34: 0 | P34: 0 | Q34: 0 | R34: 0 | S34: 0 | T34: 0 | U34: 0 | V34: 0 | W34: 0 | X34: 0 | Z34: =VLOOKUP(E34,Sheet2!$A$1:$A$39,1,0) -> #N/A | AA34: =VLOOKUP($E34,[1]Sheet1!$E$10:$X$629,AA$9,0) -> 0 | AB34: =VLOOKUP($E34,[1]Sheet1!$E$10:$X$629,AB$9,0) -> 0 | AC34: =VLOOKUP($E34,[1]Sheet1!$E$10:$X$629,AC$9,0) -> 0 | AD34: =VLOOKUP($E34,[1]Sheet1!$E$10:$X$629,AD$9,0) -> 0 | AE34: =VLOOKUP($E34,[1]Sheet1!$E$10:$X$629,AE$9,0) -> 0 | AF34: =VLOOKUP($E34,[1]Sheet1!$E$10:$X$629,AF$9,0) -> 0 | AG34: =VLOOKUP($E34,[1]Sheet1!$E$10:$X$629,AG$9,0) -> 0 | AH34: =VLOOKUP($E34,[1]Sheet1!$E$10:$X$629,AH$9,0) -> 0 | AJ34: =SUM(M34:T34) -> 0 | AK34: =SUM(AA34:AH34) -> 0 | AL34: =IFERROR(AJ34-AK34,0) -> 0
A35: 857494007219 | B35: 2547089 | C35: THE NUBIAN EYESHADOW PALETTE NUBIAN MINI | E35: 1000100 | F35: 021 | G35: 3453 - JUVIA'S PLACE | I35: DI | J35: BASC | K35: 5 | L35: 5 | M35: 0 | N35: 0 | O35: 0 | P35: 0 | Q35: 0 | R35: 0 | S35: 0 | T35: 0 | U35: 0 | V35: 0 | W35: 0 | X35: 0 | Z35: =VLOOKUP(E35,Sheet2!$A$1:$A$39,1,0) -> #N/A | AA35: =VLOOKUP($E35,[1]Sheet1!$E$10:$X$629,AA$9,0) -> 0 | AB35: =VLOOKUP($E35,[1]Sheet1!$E$10:$X$629,AB$9,0) -> 0 | AC35: =VLOOKUP($E35,[1]Sheet1!$E$10:$X$629,AC$9,0) -> 0 | AD35: =VLOOKUP($E35,[1]Sheet1!$E$10:$X$629,AD$9,0) -> 0 | AE35: =VLOOKUP($E35,[1]Sheet1!$E$10:$X$629,AE$9,0) -> 0 | AF35: =VLOOKUP($E35,[1]Sheet1!$E$10:$X$629,AF$9,0) -> 0 | AG35: =VLOOKUP($E35,[1]Sheet1!$E$10:$X$629,AG$9,0) -> 0 | AH35: =VLOOKUP($E35,[1]Sheet1!$E$10:$X$629,AH$9,0) -> 0 | AJ35: =SUM(M35:T35) -> 0 | AK35: =SUM(AA35:AH35) -> 0 | AL35: =IFERROR(AJ35-AK35,0) -> 0
A36: 857494007127 | B36: 2547607 | C36: THE HEROINE LOOSE HIGHLIGHTER | E36: 4007127 | F36: 021 | G36: 3453 - JUVIA'S PLACE | I36: X | J36: BASC | K36: 7 | L36: 6.99 | M36: 0 | N36: 0 | O36: 0 | P36: 0 | Q36: 0 | R36: 0 | S36: 0 | T36: 0 | U36: 0 | V36: 0 | W36: 0 | X36: 0 | Z36: =VLOOKUP(E36,Sheet2!$A$1:$A$39,1,0) -> #N/A | AA36: =VLOOKUP($E36,[1]Sheet1!$E$10:$X$629,AA$9,0) -> 0 | AB36: =VLOOKUP($E36,[1]Sheet1!$E$10:$X$629,AB$9,0) -> 0 | AC36: =VLOOKUP($E36,[1]Sheet1!$E$10:$X$629,AC$9,0) -> 0 | AD36: =VLOOKUP($E36,[1]Sheet1!$E$10:$X$629,AD$9,0) -> 0 | AE36: =VLOOKUP($E36,[1]Sheet1!$E$10:$X$629,AE$9,0) -> 0 | AF36: =VLOOKUP($E36,[1]Sheet1!$E$10:$X$629,AF$9,0) -> 0 | AG36: =VLOOKUP($E36,[1]Sheet1!$E$10:$X$629,AG$9,0) -> 0 | AH36: =VLOOKUP($E36,[1]Sheet1!$E$10:$X$629,AH$9,0) -> 0 | AJ36: =SUM(M36:T36) -> 0 | AK36: =SUM(AA36:AH36) -> 0 | AL36: =IFERROR(AJ36-AK36,0) -> 0
A37: 857494007103 | B37: 2547799 | C37: THE TRIBE HIGHLIGHTER | E37: 1000372 | F37: 021 | G37: 3453 - JUVIA'S PLACE | H37: C | I37: DI | J37: BASC | K37: 6 | L37: 1.2 | M37: 0 | N37: 0 | O37: 0 | P37: 0 | Q37: 0 | R37: 0 | S37: 0 | T37: 0 | U37: 0 | V37: 0 | W37: 0 | X37: 0 | Z37: =VLOOKUP(E37,Sheet2!$A$1:$A$39,1,0) -> #N/A | AA37: =VLOOKUP($E37,[1]Sheet1!$E$10:$X$629,AA$9,0) -> 0 | AB37: =VLOOKUP($E37,[1]Sheet1!$E$10:$X$629,AB$9,0) -> 0 | AC37: =VLOOKUP($E37,[1]Sheet1!$E$10:$X$629,AC$9,0) -> 0 | AD37: =VLOOKUP($E37,[1]Sheet1!$E$10:$X$629,AD$9,0) -> 0 | AE37: =VLOOKUP($E37,[1]Sheet1!$E$10:$X$629,AE$9,0) -> 0 | AF37: =VLOOKUP($E37,[1]Sheet1!$E$10:$X$629,AF$9,0) -> 0 | AG37: =VLOOKUP($E37,[1]Sheet1!$E$10:$X$629,AG$9,0) -> 0 | AH37: =VLOOKUP($E37,[1]Sheet1!$E$10:$X$629,AH$9,0) -> 0 | AJ37: =SUM(M37:T37) -> 0 | AK37: =SUM(AA37:AH37) -> 0 | AL37: =IFERROR(AJ37-AK37,0) -> 0
A38: 810018870010 | B38: 2550477 | C38: I AM MAGIC FOUNDATION 110 SENEGAL | E38: 1000112 | F38: 021 | G38: 3453 - JUVIA'S PLACE | I38: A | J38: BASC | K38: 14.4 | L38: 20 | M38: 0 | N38: 0 | O38: 0 | P38: 0 | Q38: 0 | R38: 0 | S38: 0 | T38: 0 | U38: 0 | V38: 0 | W38: 0 | X38: 0 | Z38: =VLOOKUP(E38,Sheet2!$A$1:$A$39,1,0) -> #N/A | AA38: =VLOOKUP($E38,[1]Sheet1!$E$10:$X$629,AA$9,0) -> 0 | AB38: =VLOOKUP($E38,[1]Sheet1!$E$10:$X$629,AB$9,0) -> 0 | AC38: =VLOOKUP($E38,[1]Sheet1!$E$10:$X$629,AC$9,0) -> 0 | AD38: =VLOOKUP($E38,[1]Sheet1!$E$10:$X$629,AD$9,0) -> 0 | AE38: =VLOOKUP($E38,[1]Sheet1!$E$10:$X$629,AE$9,0) -> 0 | AF38: =VLOOKUP($E38,[1]Sheet1!$E$10:$X$629,AF$9,0) -> 0 | AG38: =VLOOKUP($E38,[1]Sheet1!$E$10:$X$629,AG$9,0) -> 0 | AH38: =VLOOKUP($E38,[1]Sheet1!$E$10:$X$629,AH$9,0) -> 0 | AJ38: =SUM(M38:T38) -> 0 | AK38: =SUM(AA38:AH38) -> 0 | AL38: =IFERROR(AJ38-AK38,0) -> 0
A39: 810018870034 | B39: 2550478 | C39: I AM MAGIC FOUNDATION 130 MALI | E39: 1000114 | F39: 021 | G39: 3453 - JUVIA'S PLACE | H39: F | I39: A | J39: BASC | K39: 14.4 | L39: 20 | M39: 90 | N39: 90 | O39: 90 | P39: 0 | Q39: 0 | R39: 90 | S39: 90 | T39: 0 | U39: 180 | V39: 0 | W39: 90 | X39: 0 | Z39: =VLOOKUP(E39,Sheet2!$A$1:$A$39,1,0) -> #N/A | AA39: =VLOOKUP($E39,[1]Sheet1!$E$10:$X$629,AA$9,0) -> 90 | AB39: =VLOOKUP($E39,[1]Sheet1!$E$10:$X$629,AB$9,0) -> 180 | AC39: =VLOOKUP($E39,[1]Sheet1!$E$10:$X$629,AC$9,0) -> 180 | AD39: =VLOOKUP($E39,[1]Sheet1!$E$10:$X$629,AD$9,0) -> 180 | AE39: =VLOOKUP($E39,[1]Sheet1!$E$10:$X$629,AE$9,0) -> 0 | AF39: =VLOOKUP($E39,[1]Sheet1!$E$10:$X$629,AF$9,0) -> 270 | AG39: =VLOOKUP($E39,[1]Sheet1!$E$10:$X$629,AG$9,0) -> 180 | AH39: =VLOOKUP($E39,[1]Sheet1!$E$10:$X$629,AH$9,0) -> 0 | AJ39: =SUM(M39:T39) -> 450 | AK39: =SUM(AA39:AH39) -> 1080 | AL39: =IFERROR(AJ39-AK39,0) -> -630
A40: 810018870003 | B40: 2550479 | C40: I AM MAGIC FOUNDATION 100 SUDAN | E40: 1000111 | F40: 021 | G40: 3453 - JUVIA'S PLACE | I40: A | J40: BASC | K40: 14.4 | L40: 20 | M40: 0 | N40: 0 | O40: 0 | P40: 0 | Q40: 0 | R40: 0 | S40: 0 | T40: 0 | U40: 0 | V40: 0 | W40: 0 | X40: 0 | Z40: =VLOOKUP(E40,Sheet2!$A$1:$A$39,1,0) -> #N/A | AA40: =VLOOKUP($E40,[1]Sheet1!$E$10:$X$629,AA$9,0) -> 0 | AB40: =VLOOKUP($E40,[1]Sheet1!$E$10:$X$629,AB$9,0) -> 0 | AC40: =VLOOKUP($E40,[1]Sheet1!$E$10:$X$629,AC$9,0) -> 0 | AD40: =VLOOKUP($E40,[1]Sheet1!$E$10:$X$629,AD$9,0) -> 0 | AE40: =VLOOKUP($E40,[1]Sheet1!$E$10:$X$629,AE$9,0) -> 0 | AF40: =VLOOKUP($E40,[1]Sheet1!$E$10:$X$629,AF$9,0) -> 0 | AG40: =VLOOKUP($E40,[1]Sheet1!$E$10:$X$629,AG$9,0) -> 0 | AH40: =VLOOKUP($E40,[1]Sheet1!$E$10:$X$629,AH$9,0) -> 0 | AJ40: =SUM(M40:T40) -> 0 | AK40: =SUM(AA40:AH40) -> 0 | AL40: =IFERROR(AJ40-AK40,0) -> 0
A41: 810018870027 | B41: 2550480 | C41: I AM MAGIC FOUNDATION 120 CHAD | E41: 1000113 | F41: 021 | G41: 3453 - JUVIA'S PLACE | H41: F | I41: A | J41: BASC | K41: 14.4 | L41: 20 | M41: 90 | N41: 0 | O41: 0 | P41: 90 | Q41: 0 | R41: 0 | S41: 90 | T41: 180 | U41: 0 | V41: 90 | W41: 90 | X41: 90 | Z41: =VLOOKUP(E41,Sheet2!$A$1:$A$39,1,0) -> #N/A | AA41: =VLOOKUP($E41,[1]Sheet1!$E$10:$X$629,AA$9,0) -> 90 | AB41: =VLOOKUP($E41,[1]Sheet1!$E$10:$X$629,AB$9,0) -> 180 | AC41: =VLOOKUP($E41,[1]Sheet1!$E$10:$X$629,AC$9,0) -> 90 | AD41: =VLOOKUP($E41,[1]Sheet1!$E$10:$X$629,AD$9,0) -> 90 | AE41: =VLOOKUP($E41,[1]Sheet1!$E$10:$X$629,AE$9,0) -> 90 | AF41: =VLOOKUP($E41,[1]Sheet1!$E$10:$X$629,AF$9,0) -> 90 | AG41: =VLOOKUP($E41,[1]Sheet1!$E$10:$X$629,AG$9,0) -> 90 | AH41: =VLOOKUP($E41,[1]Sheet1!$E$10:$X$629,AH$9,0) -> 90 | AJ41: =SUM(M41:T41) -> 450 | AK41: =SUM(AA41:AH41) -> 810 | AL41: =IFERROR(AJ41-AK41,0) -> -360
A42: 810018870072 | B42: 2550481 | C42: I AM MAGIC FOUNDATION 205 TANZANIA | E42: 1000118 | F42: 021 | G42: 3453 - JUVIA'S PLACE | H42: F | I42: A | J42: BASC | K42: 14.4 | L42: 20 | M42: 0 | N42: 360 | O42: 90 | P42: 90 | Q42: 270 | R42: 90 | S42: 90 | T42: 270 | U42: 90 | V42: 180 | W42: 270 | X42: 90 | Z42: =VLOOKUP(E42,Sheet2!$A$1:$A$39,1,0) -> #N/A | AA42: =VLOOKUP($E42,[1]Sheet1!$E$10:$X$629,AA$9,0) -> 360 | AB42: =VLOOKUP($E42,[1]Sheet1!$E$10:$X$629,AB$9,0) -> 270 | AC42: =VLOOKUP($E42,[1]Sheet1!$E$10:$X$629,AC$9,0) -> 270 | AD42: =VLOOKUP($E42,[1]Sheet1!$E$10:$X$629,AD$9,0) -> 360 | AE42: =VLOOKUP($E42,[1]Sheet1!$E$10:$X$629,AE$9,0) -> 180 | AF42: =VLOOKUP($E42,[1]Sheet1!$E$10:$X$629,AF$9,0) -> 450 | AG42: =VLOOKUP($E42,[1]Sheet1!$E$10:$X$629,AG$9,0) -> 180 | AH42: =VLOOKUP($E42,[1]Sheet1!$E$10:$X$629,AH$9,0) -> 270 | AJ42: =SUM(M42:T42) -> 1260 | AK42: =SUM(AA42:AH42) -> 2340 | AL42: =IFERROR(AJ42-AK42,0) -> -1080
...

Sheet Sheet2
A1: 1200777
A2: 1200785
A3: 1200786
A4: 1200742
A5: 1200743
A6: 1200744
A7: 1200745
A8: 1200746
A9: 1200768
A10: 1200769
A11: 1200770
A12: 1200771
... A39: 1200898

Sheet Definitions_and_Disclaimer
A2: Brand Partner Order Projections
A3: Definitions and Disclaimer
A4: JUVIA'S PLACE (52853)
A5: Report Generated: 1/28/2026 8:15:30 PM
A7: Order Projections Disclaimer The projections contained in this report reflect a systematic output generated at a point of time and are subject to change based on selling patterns, changes to assortment, promotions, or ability to fulfill orders. These projected order quantities are not a guarantee of purchase and should be used as a directional estimate for planning purposes. Please reach out to your Ulta Beauty team for further assistance.
C9: Definitions
B10: Column Title | C10: UPC | D10: ULTA Item# | E10: ULTA Item Description | G10: Brand Partner SKU# | I10: Brand # | J10: Retail Item Rank | K10: Feature Code | L10: Season Code | N10: Purch Cost (Average) | O10: Retail Price (Current)
B11: Definition | C11: "Universal Product Code" is a unique identifier which may be used as an alternate to ULTA's Item number | D11: ULTA's internal identifier for a specific product | E11: ULTA's internal plain text description for a specific product | G11: A Brand Partner's internal identifier for a specific product | I11: ULTA's internal classification for like Items belonging to the same brand | J11: Enterprise performance rank given to Items based on their sales velocity in relation to other Items in retail locations | K11: Identifier given to an Item which aids in determining where an Item is sold | L11: Identifier given to an Item which determines if it is part of ULTA's base assortment, promotional, or seasonal. | N11: The average price ULTA has been charged to acquire an Item | O11: The cost that ULTA is currently charging customers for an Item
B12: Possible Values | C12: N/A | D12: N/A | E12: N/A | G12: N/A | I12: N/A | J12: A - Top 25% B - Next 25% C - Next 20% D - Next 15% E - Next 10% F - Next 5% N/A - Not assigned | K12: AA - All Stores H* - High Volatile L* - Low Volatile U* - Unique TT - Testers Z* - Discontinued | L12: BASC - Basic PROM - Promotional IO* - In and Out SE* - Seasonal | N12: N/A | O12: N/A
